[2024-03-12T03:15:42.800+0000] {taskinstance.py:1159} INFO - Dependencies all met for dep_context=non-requeueable deps ti=<TaskInstance: dag_climate.create_locations_and_forecast_tables scheduled__2024-03-01T00:00:00+00:00 [queued]>
[2024-03-12T03:15:42.804+0000] {taskinstance.py:1159} INFO - Dependencies all met for dep_context=requeueable deps ti=<TaskInstance: dag_climate.create_locations_and_forecast_tables scheduled__2024-03-01T00:00:00+00:00 [queued]>
[2024-03-12T03:15:42.805+0000] {taskinstance.py:1361} INFO - Starting attempt 4 of 4
[2024-03-12T03:15:42.810+0000] {taskinstance.py:1382} INFO - Executing <Task(PostgresOperator): create_locations_and_forecast_tables> on 2024-03-01 00:00:00+00:00
[2024-03-12T03:15:42.814+0000] {standard_task_runner.py:57} INFO - Started process 450 to run task
[2024-03-12T03:15:42.817+0000] {standard_task_runner.py:84} INFO - Running: ['***', 'tasks', 'run', 'dag_climate', 'create_locations_and_forecast_tables', 'scheduled__2024-03-01T00:00:00+00:00', '--job-id', '52', '--raw', '--subdir', 'DAGS_FOLDER/dag_climate.py', '--cfg-path', '/tmp/tmpqf98y96w']
[2024-03-12T03:15:42.817+0000] {standard_task_runner.py:85} INFO - Job 52: Subtask create_locations_and_forecast_tables
[2024-03-12T03:15:42.847+0000] {task_command.py:416} INFO - Running <TaskInstance: dag_climate.create_locations_and_forecast_tables scheduled__2024-03-01T00:00:00+00:00 [running]> on host 4828059c33e5
[2024-03-12T03:15:42.884+0000] {taskinstance.py:1662} INFO - Exporting env vars: AIRFLOW_CTX_DAG_OWNER='***' AIRFLOW_CTX_DAG_ID='dag_climate' AIRFLOW_CTX_TASK_ID='create_locations_and_forecast_tables' AIRFLOW_CTX_EXECUTION_DATE='2024-03-01T00:00:00+00:00' AIRFLOW_CTX_TRY_NUMBER='4' AIRFLOW_CTX_DAG_RUN_ID='scheduled__2024-03-01T00:00:00+00:00'
[2024-03-12T03:15:42.886+0000] {sql.py:274} INFO - Executing: CREATE TABLE IF NOT EXISTS location (
        id INT PRIMARY KEY,
        nombre VARCHAR(100)
    ) DISTSTYLE ALL SORTKEY (id);
    INSERT INTO location (id, nombre)
    VALUES
        (1, 'Buenos Aires'),
        (2, 'Córdoba'),
        (3, 'Rosario'),
        (4, 'Mendoza'),
        (5, 'San Miguel de Tucumán'),
        (6, 'La Plata'),
        (7, 'Mar del Plata'),
        (8, 'Salta'),
        (9, 'Santa Fe'),
        (10, 'San Juan'),
        (11, 'Resistencia'),
        (12, 'Santiago del Estero'),
        (13, 'Posadas'),
        (14, 'San Salvador de Jujuy'),
        (15, 'Bahía Blanca'),
        (16, 'Paraná'),
        (17, 'Merlo'),
        (18, 'José C. Paz'),
        (19, 'Quilmes'),
        (20, 'Pilar');

CREATE TABLE IF NOT EXISTS forecast (
        id INT IDENTITY(1,1) PRIMARY KEY,
        date TIMESTAMP,
        prediction_date TIMESTAMP,
        locationId INT REFERENCES location(id),
        max_temperature FLOAT,
        min_temperature FLOAT,
        precipitation_probability_max FLOAT
    ) DISTKEY (locationId) SORTKEY (date);
[2024-03-12T03:15:42.896+0000] {taskinstance.py:1937} ERROR - Task failed with exception
Traceback (most recent call last):
  File "/home/airflow/.local/lib/python3.8/site-packages/airflow/providers/common/sql/operators/sql.py", line 275, in execute
    hook = self.get_db_hook()
  File "/home/airflow/.local/lib/python3.8/site-packages/airflow/providers/common/sql/operators/sql.py", line 186, in get_db_hook
    return self._hook
  File "/usr/local/lib/python3.8/functools.py", line 967, in __get__
    val = self.func(instance)
  File "/home/airflow/.local/lib/python3.8/site-packages/airflow/providers/common/sql/operators/sql.py", line 148, in _hook
    conn = BaseHook.get_connection(conn_id)
  File "/home/airflow/.local/lib/python3.8/site-packages/airflow/hooks/base.py", line 72, in get_connection
    conn = Connection.get_connection_from_secrets(conn_id)
  File "/home/airflow/.local/lib/python3.8/site-packages/airflow/models/connection.py", line 477, in get_connection_from_secrets
    raise AirflowNotFoundException(f"The conn_id `{conn_id}` isn't defined")
airflow.exceptions.AirflowNotFoundException: The conn_id `coderhouse_connection` isn't defined
[2024-03-12T03:15:42.899+0000] {taskinstance.py:1400} INFO - Marking task as FAILED. dag_id=dag_climate, task_id=create_locations_and_forecast_tables, execution_date=20240301T000000, start_date=20240312T031542, end_date=20240312T031542
[2024-03-12T03:15:42.903+0000] {standard_task_runner.py:104} ERROR - Failed to execute job 52 for task create_locations_and_forecast_tables (The conn_id `coderhouse_connection` isn't defined; 450)
[2024-03-12T03:15:42.911+0000] {local_task_job_runner.py:228} INFO - Task exited with return code 1
[2024-03-12T03:15:42.925+0000] {taskinstance.py:2778} INFO - 0 downstream tasks scheduled from follow-on schedule check
