[2024-03-12T03:22:16.527+0000] {taskinstance.py:1159} INFO - Dependencies all met for dep_context=non-requeueable deps ti=<TaskInstance: dag_climate.insert_forecast_data manual__2024-03-12T03:18:41.907647+00:00 [queued]>
[2024-03-12T03:22:16.532+0000] {taskinstance.py:1159} INFO - Dependencies all met for dep_context=requeueable deps ti=<TaskInstance: dag_climate.insert_forecast_data manual__2024-03-12T03:18:41.907647+00:00 [queued]>
[2024-03-12T03:22:16.532+0000] {taskinstance.py:1361} INFO - Starting attempt 4 of 4
[2024-03-12T03:22:16.537+0000] {taskinstance.py:1382} INFO - Executing <Task(PythonOperator): insert_forecast_data> on 2024-03-12 03:18:41.907647+00:00
[2024-03-12T03:22:16.542+0000] {standard_task_runner.py:57} INFO - Started process 732 to run task
[2024-03-12T03:22:16.544+0000] {standard_task_runner.py:84} INFO - Running: ['***', 'tasks', 'run', 'dag_climate', 'insert_forecast_data', 'manual__2024-03-12T03:18:41.907647+00:00', '--job-id', '80', '--raw', '--subdir', 'DAGS_FOLDER/dag_climate.py', '--cfg-path', '/tmp/tmpnza392mu']
[2024-03-12T03:22:16.545+0000] {standard_task_runner.py:85} INFO - Job 80: Subtask insert_forecast_data
[2024-03-12T03:22:16.579+0000] {task_command.py:416} INFO - Running <TaskInstance: dag_climate.insert_forecast_data manual__2024-03-12T03:18:41.907647+00:00 [running]> on host 4828059c33e5
[2024-03-12T03:22:16.623+0000] {taskinstance.py:1662} INFO - Exporting env vars: AIRFLOW_CTX_DAG_OWNER='***' AIRFLOW_CTX_DAG_ID='dag_climate' AIRFLOW_CTX_TASK_ID='insert_forecast_data' AIRFLOW_CTX_EXECUTION_DATE='2024-03-12T03:18:41.907647+00:00' AIRFLOW_CTX_TRY_NUMBER='4' AIRFLOW_CTX_DAG_RUN_ID='manual__2024-03-12T03:18:41.907647+00:00'
[2024-03-12T03:22:17.873+0000] {taskinstance.py:1937} ERROR - Task failed with exception
Traceback (most recent call last):
  File "/home/airflow/.local/lib/python3.8/site-packages/airflow/operators/python.py", line 192, in execute
    return_value = self.execute_callable()
  File "/home/airflow/.local/lib/python3.8/site-packages/airflow/operators/python.py", line 209, in execute_callable
    return self.python_callable(*self.op_args, **self.op_kwargs)
  File "/opt/airflow/scripts/main.py", line 129, in insert_forecast_data
    cur = conn.cursor()
  File "/home/airflow/.local/lib/python3.8/site-packages/airflow/utils/context.py", line 127, in __getattr__
    self.var = Connection.get_connection_from_secrets(key)
  File "/home/airflow/.local/lib/python3.8/site-packages/airflow/models/connection.py", line 477, in get_connection_from_secrets
    raise AirflowNotFoundException(f"The conn_id `{conn_id}` isn't defined")
airflow.exceptions.AirflowNotFoundException: The conn_id `cursor` isn't defined
[2024-03-12T03:22:17.876+0000] {taskinstance.py:1400} INFO - Marking task as FAILED. dag_id=dag_climate, task_id=insert_forecast_data, execution_date=20240312T031841, start_date=20240312T032216, end_date=20240312T032217
[2024-03-12T03:22:17.881+0000] {standard_task_runner.py:104} ERROR - Failed to execute job 80 for task insert_forecast_data (The conn_id `cursor` isn't defined; 732)
[2024-03-12T03:22:17.893+0000] {local_task_job_runner.py:228} INFO - Task exited with return code 1
[2024-03-12T03:22:17.910+0000] {taskinstance.py:2778} INFO - 0 downstream tasks scheduled from follow-on schedule check
